Workbook

Sheet Notes
A1: Log Adviser
A2: A spreadsheet by Main Mukkor
A3: Release version: | B3: ='Change log and credits'!$A$2 -> v 1.3.4 | C3: ='Change log and credits'!$B$2 -> 46001
A4: Check the #log-adviser channel in the Log Hunters Discord server to see how to give feedback.
A6: How to use this sheet:
A7: If you want to know which activities give fast log slots for a beginner:
A8: 1. Go to the "List of activities" tab and create a filtered view.
A9: Data -> Create filter view
A11: 2. Sort the "Time to next log slot" column in the filter view from A-Z.
A13: If you want to know which activities give the fastest log slots for you:
A14: 1. Sign in to your Google account.
A16: 2. Make a copy (File -> Make a copy) and use that copy.
A18: 3. Upload your log using the TempleOSRS plugin.*
A19: a. Make sure your templeosrs.com profile exists. If it doesn't,
A20: search for your username, then press the "Update Player" button.
... A25: You can check if it worked by viewing the "Collection Log" tab of your Temple profile.
A26: * You could use the manual override feature on the "List of log slots" tab if you don't want to do an automatic import (click the check boxes), then skip to step 5. | E26: Use Ironman rates
A27: 4. Input your username to automatically import your log: | E27: FALSE
A28: You can refresh by changing the username here if you're using the Temple API.
A29: You'll have to press "Temple sync" for each new log unless you set up auto-sync.
A30: Check the checkbox if you're an Ironman to use Ironman rates instead of Main rates.
A32: 5. Go to the "List of activities" tab and create a filtered view.
A33: Data -> Create filter view
A35: 6. Sort the "Time to next log slot" column in the filter view from A-Z.
A37: Other cool stuff you can do:
A38: Sort by other columns!
A39: Try sorting by "Slots left" or "% complete" or "Difficulty" instead of "Time to next log slot".
A41: Difficulty stats and filtering!
A42: Check out the "Difficulty stats" tab to check your progress on collection logs for each difficulty rating from 1-10.
A43: Also try filtering the "List of log slots" by difficulty rating! Create a filter view, then click the top right of the slot
... A61: I'm looking for suggestions! What features would you like to see added to Log Adviser?
A63: Items without an activity: | E63: Count:
A64: Barronite mace (0 time reward for getting the 3 pieces) | E64: 1
A65: Champion's cape (Basically 0 time reward for finishing the rest of the Champion's Challenge log) | E65: 1
A66: Total: | E66: =SUM(E63:E65) -> 2

Sheet List of activities
A1: Index | B1: Activity name | C1: Completions/hr | D1: Extra time to first completion (hours) | E1: Effective droprate (neither) | F1: Time to neither | G1: Effective droprate (independent) | H1: Time to independent | I1: Effective droprate (exact) | J1: Time to exact | K1: Effective droprate (E&I) | L1: Time to E&I | M1: Fastest Item ID | N1: Easiest Item ID | O1: Time to next log slot | P1: Fastest slot | Q1: Slots left | R1: Slots total | S1: % complete | T1: Difficulty | U1: Easiest slot
A2: 211 | B2: =VLOOKUP($A2, 'Completion rates'!$A:$E, 2, FALSE) -> Killing gryphons (on task) | C2: =IF(Notes!$E$27, VLOOKUP($A2, 'Completion rates'!$A:$E, 4, FALSE), VLOOKUP($A2, 'Completion rates'!$A:$E, 3, FALSE)) -> 600 | D2: =VLOOKUP($A2, 'Completion rates'!$A:$E, 5, FALSE) -> 0 | E2: =IF(SUMIFS('Activity map'!$O:$O, 'Activity map'!$A:$A, A2, 'Activity map'!$H:$H, "=TRUE") = 0, "n/a", 1/SUMIFS('Activity map'!$O:$O, 'Activity map'!$A:$A, A2, 'Activity map'!$H:$H, "=TRUE")) -> 0.99993661 | F2: =IF(OR(ISBLANK(C2), E2 = "n/a"), "", E2/C2 + D2) -> 0.001666561 | G2: =IF(MINIFS('Activity map'!$N:$N, 'Activity map'!$A:$A, A2, 'Activity map'!$H:$H, "=TRUE") = 0, "n/a", MINIFS('Activity map'!$N:$N, 'Activity map'!$A:$A, A2, 'Activity map'!$H:$H, "=TRUE")) -> n/a | H2: =IF(OR(ISBLANK(C2), G2 = "n/a"), "", G2/C2 + D2) | I2: =IF(MINIFS('Activity map'!$M:$M, 'Activity map'!$A:$A, A2, 'Activity map'!$H:$H, "=TRUE") = 0, "n/a", MINIFS('Activity map'!$M:$M, 'Activity map'!$A:$A, A2, 'Activity map'!$H:$H, "=TRUE")) -> 1000 | J2: =IF(OR(ISBLANK(C2), I2 = "n/a"), "", I2/C2 + D2) -> 1.6666667 | K2: =IF(MINIFS('Activity map'!$L:$L, 'Activity map'!$A:$A, A2, 'Activity map'!$H:$H, "=TRUE") = 0, "n/a", MINIFS('Activity map'!$L:$L, 'Activity map'!$A:$A, A2, 'Activity map'!$H:$H, "=TRUE")) -> n/a | L2: =IF(OR(ISBLANK(C2), K2 = "n/a"), "", K2/C2 + D2) | M2: =MINIFS('Activity map'!$C:$C, 'Activity map'!$A:$A, $A2, 'Activity map'!$H:$H, "=TRUE", 'Activity map'!$K:$K, MINIFS('Activity map'!$K:$K, 'Activity map'!$A:$A, $A2, 'Activity map'!$H:$H, "=TRUE")) -> 31235 | N2: =MINIFS('Activity map'!$C:$C, 'Activity map'!$A:$A, $A2, 'Activity map'!$H:$H, "=TRUE", 'Activity map'!$E:$E, $T2) -> 31235 | O2: =IF(MIN(F2,H2,J2,L2) = 0, "Done!", MIN(F2,H2,J2,L2) / 24) -> 6.9440042e-05 | P2: =IF($M2=0, "-", VLOOKUP($M2, 'List of log slots'!$A:$C, 2, FALSE)) -> Gryphon feather | Q2: =IFERROR(__xludf.DUMMYFUNCTION("IF(ISERROR(FILTER('Activity map'!$C:$C, ('Activity map'!$A:$A=$A2)*('Activity map'!$F:$F=FALSE))), 0, COUNTA(UNIQUE(FILTER('Activity map'!$C:$C, ('Activity map'!$A:$A=$A2)*('Activity map'!$F:$F=FALSE)))))"),8.0) -> 8 | R2: =IFERROR(__xludf.DUMMYFUNCTION("IF(ISERROR(FILTER('Activity map'!$C:$C, 'Activity map'!$A:$A=$A2)), 0, COUNTA(UNIQUE(FILTER('Activity map'!$C:$C, 'Activity map'!$A:$A=$A2))))"),8.0) -> 8 | S2: =1 - Q2/R2 -> 0 | T2: =IFERROR(__xludf.DUMMYFUNCTION("IF(ISERROR(FILTER('Activity map'!$E:$E, ('Activity map'!$A:$A=$A2)*('Activity map'!$F:$F=FALSE))), ""-"", MIN(UNIQUE(FILTER('Activity map'!$E:$E, ('Activity map'!$A:$A=$A2)*('Activity map'!$F:$F=FALSE)))))"),4.0) -> 4 | U2: =IF($N2=0, "-", VLOOKUP($N2, 'List of log slots'!$A:$C, 2, FALSE)) -> Gryphon feather
A3: 208 | B3: =VLOOKUP($A3, 'Completion rates'!$A:$E, 2, FALSE) -> Killing araxytes (level 146, on task) | C3: =IF(Notes!$E$27, VLOOKUP($A3, 'Completion rates'!$A:$E, 4, FALSE), VLOOKUP($A3, 'Completion rates'!$A:$E, 3, FALSE)) -> 500 | D3: =VLOOKUP($A3, 'Completion rates'!$A:$E, 5, FALSE) -> 0 | E3: =IF(SUMIFS('Activity map'!$O:$O, 'Activity map'!$A:$A, A3, 'Activity map'!$H:$H, "=TRUE") = 0, "n/a", 1/SUMIFS('Activity map'!$O:$O, 'Activity map'!$A:$A, A3, 'Activity map'!$H:$H, "=TRUE")) -> 0.99801585 | F3: =IF(OR(ISBLANK(C3), E3 = "n/a"), "", E3/C3 + D3) -> 0.0019960317 | G3: =IF(MINIFS('Activity map'!$N:$N, 'Activity map'!$A:$A, A3, 'Activity map'!$H:$H, "=TRUE") = 0, "n/a", MINIFS('Activity map'!$N:$N, 'Activity map'!$A:$A, A3, 'Activity map'!$H:$H, "=TRUE")) -> n/a | H3: =IF(OR(ISBLANK(C3), G3 = "n/a"), "", G3/C3 + D3) | I3: =IF(MINIFS('Activity map'!$M:$M, 'Activity map'!$A:$A, A3, 'Activity map'!$H:$H, "=TRUE") = 0, "n/a", MINIFS('Activity map'!$M:$M, 'Activity map'!$A:$A, A3, 'Activity map'!$H:$H, "=TRUE")) -> n/a | J3: =IF(OR(ISBLANK(C3), I3 = "n/a"), "", I3/C3 + D3) | K3: =IF(MINIFS('Activity map'!$L:$L, 'Activity map'!$A:$A, A3, 'Activity map'!$H:$H, "=TRUE") = 0, "n/a", MINIFS('Activity map'!$L:$L, 'Activity map'!$A:$A, A3, 'Activity map'!$H:$H, "=TRUE")) -> n/a | L3: =IF(OR(ISBLANK(C3), K3 = "n/a"), "", K3/C3 + D3) | M3: =MINIFS('Activity map'!$C:$C, 'Activity map'!$A:$A, $A3, 'Activity map'!$H:$H, "=TRUE", 'Activity map'!$K:$K, MINIFS('Activity map'!$K:$K, 'Activity map'!$A:$A, $A3, 'Activity map'!$H:$H, "=TRUE")) -> 29784 | N3: =MINIFS('Activity map'!$C:$C, 'Activity map'!$A:$A, $A3, 'Activity map'!$H:$H, "=TRUE", 'Activity map'!$E:$E, $T3) -> 29784 | O3: =IF(MIN(F3,H3,J3,L3) = 0, "Done!", MIN(F3,H3,J3,L3) / 24) -> 8.3167987e-05 | P3: =IF($M3=0, "-", VLOOKUP($M3, 'List of log slots'!$A:$C, 2, FALSE)) -> Araxyte venom sack | Q3: =IFERROR(__xludf.DUMMYFUNCTION("IF(ISERROR(FILTER('Activity map'!$C:$C, ('Activity map'!$A:$A=$A3)*('Activity map'!$F:$F=FALSE))), 0, COUNTA(UNIQUE(FILTER('Activity map'!$C:$C, ('Activity map'!$A:$A=$A3)*('Activity map'!$F:$F=FALSE)))))"),7.0) -> 7 | R3: =IFERROR(__xludf.DUMMYFUNCTION("IF(ISERROR(FILTER('Activity map'!$C:$C, 'Activity map'!$A:$A=$A3)), 0, COUNTA(UNIQUE(FILTER('Activity map'!$C:$C, 'Activity map'!$A:$A=$A3))))"),7.0) -> 7 | S3: =1 - Q3/R3 -> 0 | T3: =IFERROR(__xludf.DUMMYFUNCTION("IF(ISERROR(FILTER('Activity map'!$E:$E, ('Activity map'!$A:$A=$A3)*('Activity map'!$F:$F=FALSE))), ""-"", MIN(UNIQUE(FILTER('Activity map'!$E:$E, ('Activity map'!$A:$A=$A3)*('Activity map'!$F:$F=FALSE)))))"),5.0) -> 5 | U3: =IF($N3=0, "-", VLOOKUP($N3, 'List of log slots'!$A:$C, 2, FALSE)) -> Araxyte venom sack
A4: 127 | B4: =VLOOKUP($A4, 'Completion rates'!$A:$E, 2, FALSE) -> Spending 100 numulite at the fossil island notes chest | C4: =IF(Notes!$E$27, VLOOKUP($A4, 'Completion rates'!$A:$E, 4, FALSE), VLOOKUP($A4, 'Completion rates'!$A:$E, 3, FALSE)) -> 1000 | D4: =VLOOKUP($A4, 'Completion rates'!$A:$E, 5, FALSE) -> 0 | E4: =IF(SUMIFS('Activity map'!$O:$O, 'Activity map'!$A:$A, A4, 'Activity map'!$H:$H, "=TRUE") = 0, "n/a", 1/SUMIFS('Activity map'!$O:$O, 'Activity map'!$A:$A, A4, 'Activity map'!$H:$H, "=TRUE")) -> n/a | F4: =IF(OR(ISBLANK(C4), E4 = "n/a"), "", E4/C4 + D4) | G4: =IF(MINIFS('Activity map'!$N:$N, 'Activity map'!$A:$A, A4, 'Activity map'!$H:$H, "=TRUE") = 0, "n/a", MINIFS('Activity map'!$N:$N, 'Activity map'!$A:$A, A4, 'Activity map'!$H:$H, "=TRUE")) -> 3 | H4: =IF(OR(ISBLANK(C4), G4 = "n/a"), "", G4/C4 + D4) -> 0.003 | I4: =IF(MINIFS('Activity map'!$M:$M, 'Activity map'!$A:$A, A4, 'Activity map'!$H:$H, "=TRUE") = 0, "n/a", MINIFS('Activity map'!$M:$M, 'Activity map'!$A:$A, A4, 'Activity map'!$H:$H, "=TRUE")) -> n/a | J4: =IF(OR(ISBLANK(C4), I4 = "n/a"), "", I4/C4 + D4) | K4: =IF(MINIFS('Activity map'!$L:$L, 'Activity map'!$A:$A, A4, 'Activity map'!$H:$H, "=TRUE") = 0, "n/a", MINIFS('Activity map'!$L:$L, 'Activity map'!$A:$A, A4, 'Activity map'!$H:$H, "=TRUE")) -> n/a | L4: =IF(OR(ISBLANK(C4), K4 = "n/a"), "", K4/C4 + D4) | M4: =MINIFS('Activity map'!$C:$C, 'Activity map'!$A:$A, $A4, 'Activity map'!$H:$H, "=TRUE", 'Activity map'!$K:$K, MINIFS('Activity map'!$K:$K, 'Activity map'!$A:$A, $A4, 'Activity map'!$H:$H, "=TRUE")) -> 21664 | N4: =MINIFS('Activity map'!$C:$C, 'Activity map'!$A:$A, $A4, 'Activity map'!$H:$H, "=TRUE", 'Activity map'!$E:$E, $T4) -> 21664 | O4: =IF(MIN(F4,H4,J4,L4) = 0, "Done!", MIN(F4,H4,J4,L4) / 24) -> 0.000125 | P4: =IF($M4=0, "-", VLOOKUP($M4, 'List of log slots'!$A:$C, 2, FALSE)) -> Scribbled note | Q4: =IFERROR(__xludf.DUMMYFUNCTION("IF(ISERROR(FILTER('Activity map'!$C:$C, ('Activity map'!$A:$A=$A4)*('Activity map'!$F:$F=FALSE))), 0, COUNTA(UNIQUE(FILTER('Activity map'!$C:$C, ('Activity map'!$A:$A=$A4)*('Activity map'!$F:$F=FALSE)))))"),10.0) -> 10 | R4: =IFERROR(__xludf.DUMMYFUNCTION("IF(ISERROR(FILTER('Activity map'!$C:$C, 'Activity map'!$A:$A=$A4)), 0, COUNTA(UNIQUE(FILTER('Activity map'!$C:$C, 'Activity map'!$A:$A=$A4))))"),10.0) -> 10 | S4: =1 - Q4/R4 -> 0 | T4: =IFERROR(__xludf.DUMMYFUNCTION("IF(ISERROR(FILTER('Activity map'!$E:$E, ('Activity map'!$A:$A=$A4)*('Activity map'!$F:$F=FALSE))), ""-"", MIN(UNIQUE(FILTER('Activity map'!$E:$E, ('Activity map'!$A:$A=$A4)*('Activity map'!$F:$F=FALSE)))))"),2.0) -> 2 | U4: =IF($N4=0, "-", VLOOKUP($N4, 'List of log slots'!$A:$C, 2, FALSE)) -> Scribbled note
A5: 136 | B5: =VLOOKUP($A5, 'Completion rates'!$A:$E, 2, FALSE) -> Killing revenants (demon cyclops quads, skulled, off task) | C5: =IF(Notes!$E$27, VLOOKUP($A5, 'Completion rates'!$A:$E, 4, FALSE), VLOOKUP($A5, 'Completion rates'!$A:$E, 3, FALSE)) -> 260 | D5: =VLOOKUP($A5, 'Completion rates'!$A:$E, 5, FALSE) -> 0 | E5: =IF(SUMIFS('Activity map'!$O:$O, 'Activity map'!$A:$A, A5, 'Activity map'!$H:$H, "=TRUE") = 0, "n/a", 1/SUMIFS('Activity map'!$O:$O, 'Activity map'!$A:$A, A5, 'Activity map'!$H:$H, "=TRUE")) -> 7.7109675 | F5: =IF(OR(ISBLANK(C5), E5 = "n/a"), "", E5/C5 + D5) -> 0.029657567 | G5: =IF(MINIFS('Activity map'!$N:$N, 'Activity map'!$A:$A, A5, 'Activity map'!$H:$H, "=TRUE") = 0, "n/a", MINIFS('Activity map'!$N:$N, 'Activity map'!$A:$A, A5, 'Activity map'!$H:$H, "=TRUE")) -> n/a | H5: =IF(OR(ISBLANK(C5), G5 = "n/a"), "", G5/C5 + D5) | I5: =IF(MINIFS('Activity map'!$M:$M, 'Activity map'!$A:$A, A5, 'Activity map'!$H:$H, "=TRUE") = 0, "n/a", MINIFS('Activity map'!$M:$M, 'Activity map'!$A:$A, A5, 'Activity map'!$H:$H, "=TRUE")) -> 1 | J5: =IF(OR(ISBLANK(C5), I5 = "n/a"), "", I5/C5 + D5) -> 0.0038461538 | K5: =IF(MINIFS('Activity map'!$L:$L, 'Activity map'!$A:$A, A5, 'Activity map'!$H:$H, "=TRUE") = 0, "n/a", MINIFS('Activity map'!$L:$L, 'Activity map'!$A:$A, A5, 'Activity map'!$H:$H, "=TRUE")) -> n/a | L5: =IF(OR(ISBLANK(C5), K5 = "n/a"), "", K5/C5 + D5) | M5: =MINIFS('Activity map'!$C:$C, 'Activity map'!$A:$A, $A5, 'Activity map'!$H:$H, "=TRUE", 'Activity map'!$K:$K, MINIFS('Activity map'!$K:$K, 'Activity map'!$A:$A, $A5, 'Activity map'!$H:$H, "=TRUE")) -> 21820 | N5: =MINIFS('Activity map'!$C:$C, 'Activity map'!$A:$A, $A5, 'Activity map'!$H:$H, "=TRUE", 'Activity map'!$E:$E, $T5) -> 21820 | O5: =IF(MIN(F5,H5,J5,L5) = 0, "Done!", MIN(F5,H5,J5,L5) / 24) -> 0.00016025641 | P5: =IF($M5=0, "-", VLOOKUP($M5, 'List of log slots'!$A:$C, 2, FALSE)) -> Revenant ether | Q5: =IFERROR(__xludf.DUMMYFUNCTION("IF(ISERROR(FILTER('Activity map'!$C:$C, ('Activity map'!$A:$A=$A5)*('Activity map'!$F:$F=FALSE))), 0, COUNTA(UNIQUE(FILTER('Activity map'!$C:$C, ('Activity map'!$A:$A=$A5)*('Activity map'!$F:$F=FALSE)))))"),14.0) -> 14 | R5: =IFERROR(__xludf.DUMMYFUNCTION("IF(ISERROR(FILTER('Activity map'!$C:$C, 'Activity map'!$A:$A=$A5)), 0, COUNTA(UNIQUE(FILTER('Activity map'!$C:$C, 'Activity map'!$A:$A=$A5))))"),14.0) -> 14 | S5: =1 - Q5/R5 -> 0 | T5: =IFERROR(__xludf.DUMMYFUNCTION("IF(ISERROR(FILTER('Activity map'!$E:$E, ('Activity map'!$A:$A=$A5)*('Activity map'!$F:$F=FALSE))), ""-"", MIN(UNIQUE(FILTER('Activity map'!$E:$E, ('Activity map'!$A:$A=$A5)*('Activity map'!$F:$F=FALSE)))))"),1.0) -> 1 | U5: =IF($N5=0, "-", VLOOKUP($N5, 'List of log slots'!$A:$C, 2, FALSE)) -> Revenant ether
A6: 85 | B6: =VLOOKUP($A6, 'Completion rates'!$A:$E, 2, FALSE) -> Looting hallowed marks (hallowed sepulchre) | C6: =IF(Notes!$E$27, VLOOKUP($A6, 'Completion rates'!$A:$E, 4, FALSE), VLOOKUP($A6, 'Completion rates'!$A:$E, 3, FALSE)) -> 160 | D6: =VLOOKUP($A6, 'Completion rates'!$A:$E, 5, FALSE) -> 0 | E6: =IF(SUMIFS('Activity map'!$O:$O, 'Activity map'!$A:$A, A6, 'Activity map'!$H:$H, "=TRUE") = 0, "n/a", 1/SUMIFS('Activity map'!$O:$O, 'Activity map'!$A:$A, A6, 'Activity map'!$H:$H, "=TRUE")) -> 30.146667 | F6: =IF(OR(ISBLANK(C6), E6 = "n/a"), "", E6/C6 + D6) -> 0.18841667 | G6: =IF(MINIFS('Activity map'!$N:$N, 'Activity map'!$A:$A, A6, 'Activity map'!$H:$H, "=TRUE") = 0, "n/a", MINIFS('Activity map'!$N:$N, 'Activity map'!$A:$A, A6, 'Activity map'!$H:$H, "=TRUE")) -> 10 | H6: =IF(OR(ISBLANK(C6), G6 = "n/a"), "", G6/C6 + D6) -> 0.0625 | I6: =IF(MINIFS('Activity map'!$M:$M, 'Activity map'!$A:$A, A6, 'Activity map'!$H:$H, "=TRUE") = 0, "n/a", MINIFS('Activity map'!$M:$M, 'Activity map'!$A:$A, A6, 'Activity map'!$H:$H, "=TRUE")) -> 1 | J6: =IF(OR(ISBLANK(C6), I6 = "n/a"), "", I6/C6 + D6) -> 0.00625 | K6: =IF(MINIFS('Activity map'!$L:$L, 'Activity map'!$A:$A, A6, 'Activity map'!$H:$H, "=TRUE") = 0, "n/a", MINIFS('Activity map'!$L:$L, 'Activity map'!$A:$A, A6, 'Activity map'!$H:$H, "=TRUE")) -> n/a | L6: =IF(OR(ISBLANK(C6), K6 = "n/a"), "", K6/C6 + D6) | M6: =MINIFS('Activity map'!$C:$C, 'Activity map'!$A:$A, $A6, 'Activity map'!$H:$H, "=TRUE", 'Activity map'!$K:$K, MINIFS('Activity map'!$K:$K, 'Activity map'!$A:$A, $A6, 'Activity map'!$H:$H, "=TRUE")) -> 24711 | N6: =MINIFS('Activity map'!$C:$C, 'Activity map'!$A:$A, $A6, 'Activity map'!$H:$H, "=TRUE", 'Activity map'!$E:$E, $T6) -> 24711 | O6: =IF(MIN(F6,H6,J6,L6) = 0, "Done!", MIN(F6,H6,J6,L6) / 24) -> 0.00026041667 | P6: =IF($M6=0, "-", VLOOKUP($M6, 'List of log slots'!$A:$C, 2, FALSE)) -> Hallowed mark | Q6: =IFERROR(__xludf.DUMMYFUNCTION("IF(ISERROR(FILTER('Activity map'!$C:$C, ('Activity map'!$A:$A=$A6)*('Activity map'!$F:$F=FALSE))), 0, COUNTA(UNIQUE(FILTER('Activity map'!$C:$C, ('Activity map'!$A:$A=$A6)*('Activity map'!$F:$F=FALSE)))))"),15.0) -> 15 | R6: =IFERROR(__xludf.DUMMYFUNCTION("IF(ISERROR(FILTER('Activity map'!$C:$C, 'Activity map'!$A:$A=$A6)), 0, COUNTA(UNIQUE(FILTER('Activity map'!$C:$C, 'Activity map'!$A:$A=$A6))))"),15.0) -> 15 | S6: =1 - Q6/R6 -> 0 | T6: =IFERROR(__xludf.DUMMYFUNCTION("IF(ISERROR(FILTER('Activity map'!$E:$E, ('Activity map'!$A:$A=$A6)*('Activity map'!$F:$F=FALSE))), ""-"", MIN(UNIQUE(FILTER('Activity map'!$E:$E, ('Activity map'!$A:$A=$A6)*('Activity map'!$F:$F=FALSE)))))"),4.0) -> 4 | U6: =IF($N6=0, "-", VLOOKUP($N6, 'List of log slots'!$A:$C, 2, FALSE)) -> Hallowed mark
A7: 81 | B7: =VLOOKUP($A7, 'Completion rates'!$A:$E, 2, FALSE) -> Earning giants' foundry reputation | C7: =IF(Notes!$E$27, VLOOKUP($A7, 'Completion rates'!$A:$E, 4, FALSE), VLOOKUP($A7, 'Completion rates'!$A:$E, 3, FALSE)) -> 2000 | D7: =VLOOKUP($A7, 'Completion rates'!$A:$E, 5, FALSE) -> 0 | E7: =IF(SUMIFS('Activity map'!$O:$O, 'Activity map'!$A:$A, A7, 'Activity map'!$H:$H, "=TRUE") = 0, "n/a", 1/SUMIFS('Activity map'!$O:$O, 'Activity map'!$A:$A, A7, 'Activity map'!$H:$H, "=TRUE")) -> n/a | F7: =IF(OR(ISBLANK(C7), E7 = "n/a"), "", E7/C7 + D7) | G7: =IF(MINIFS('Activity map'!$N:$N, 'Activity map'!$A:$A, A7, 'Activity map'!$H:$H, "=TRUE") = 0, "n/a", MINIFS('Activity map'!$N:$N, 'Activity map'!$A:$A, A7, 'Activity map'!$H:$H, "=TRUE")) -> n/a | H7: =IF(OR(ISBLANK(C7), G7 = "n/a"), "", G7/C7 + D7) | I7: =IF(MINIFS('Activity map'!$M:$M, 'Activity map'!$A:$A, A7, 'Activity map'!$H:$H, "=TRUE") = 0, "n/a", MINIFS('Activity map'!$M:$M, 'Activity map'!$A:$A, A7, 'Activity map'!$H:$H, "=TRUE")) -> n/a | J7: =IF(OR(ISBLANK(C7), I7 = "n/a"), "", I7/C7 + D7) | K7: =IF(MINIFS('Activity map'!$L:$L, 'Activity map'!$A:$A, A7, 'Activity map'!$H:$H, "=TRUE") = 0, "n/a", MINIFS('Activity map'!$L:$L, 'Activity map'!$A:$A, A7, 'Activity map'!$H:$H, "=TRUE")) -> 15 | L7: =IF(OR(ISBLANK(C7), K7 = "n/a"), "", K7/C7 + D7) -> 0.0075 | M7: =MINIFS('Activity map'!$C:$C, 'Activity map'!$A:$A, $A7, 'Activity map'!$H:$H, "=TRUE", 'Activity map'!$K:$K, MINIFS('Activity map'!$K:$K, 'Activity map'!$A:$A, $A7, 'Activity map'!$H:$H, "=TRUE")) -> 27017 | N7: =MINIFS('Activity map'!$C:$C, 'Activity map'!$A:$A, $A7, 'Activity map'!$H:$H, "=TRUE", 'Activity map'!$E:$E, $T7) -> 27014 | O7: =IF(MIN(F7,H7,J7,L7) = 0, "Done!", MIN(F7,H7,J7,L7) / 24) -> 0.0003125 | P7: =IF($M7=0, "-", VLOOKUP($M7, 'List of log slots'!$A:$C, 2, FALSE)) -> Smithing catalyst | Q7: =IFERROR(__xludf.DUMMYFUNCTION("IF(ISERROR(FILTER('Activity map'!$C:$C, ('Activity map'!$A:$A=$A7)*('Activity map'!$F:$F=FALSE))), 0, COUNTA(UNIQUE(FILTER('Activity map'!$C:$C, ('Activity map'!$A:$A=$A7)*('Activity map'!$F:$F=FALSE)))))"),9.0) -> 9 | R7: =IFERROR(__xludf.DUMMYFUNCTION("IF(ISERROR(FILTER('Activity map'!$C:$C, 'Activity map'!$A:$A=$A7)), 0, COUNTA(UNIQUE(FILTER('Activity map'!$C:$C, 'Activity map'!$A:$A=$A7))))"),9.0) -> 9 | S7: =1 - Q7/R7 -> 0 | T7: =IFERROR(__xludf.DUMMYFUNCTION("IF(ISERROR(FILTER('Activity map'!$E:$E, ('Activity map'!$A:$A=$A7)*('Activity map'!$F:$F=FALSE))), ""-"", MIN(UNIQUE(FILTER('Activity map'!$E:$E, ('Activity map'!$A:$A=$A7)*('Activity map'!$F:$F=FALSE)))))"),1.0) -> 1 | U7: =IF($N7=0, "-", VLOOKUP($N7, 'List of log slots'!$A:$C, 2, FALSE)) -> Kovac's grog
A8: 94 | B8: =VLOOKUP($A8, 'Completion rates'!$A:$E, 2, FALSE) -> Opening chests with shades of mort'ton keys | C8: =IF(Notes!$E$27, VLOOKUP($A8, 'Completion rates'!$A:$E, 4, FALSE), VLOOKUP($A8, 'Completion rates'!$A:$E, 3, FALSE)) -> 175 | D8: =VLOOKUP($A8, 'Completion rates'!$A:$E, 5, FALSE) -> 0 | E8: =IF(SUMIFS('Activity map'!$O:$O, 'Activity map'!$A:$A, A8, 'Activity map'!$H:$H, "=TRUE") = 0, "n/a", 1/SUMIFS('Activity map'!$O:$O, 'Activity map'!$A:$A, A8, 'Activity map'!$H:$H, "=TRUE")) -> 1.3300346 | F8: =IF(OR(ISBLANK(C8), E8 = "n/a"), "", E8/C8 + D8) -> 0.0076001979 | G8: =IF(MINIFS('Activity map'!$N:$N, 'Activity map'!$A:$A, A8, 'Activity map'!$H:$H, "=TRUE") = 0, "n/a", MINIFS('Activity map'!$N:$N, 'Activity map'!$A:$A, A8, 'Activity map'!$H:$H, "=TRUE")) -> 60 | H8: =IF(OR(ISBLANK(C8), G8 = "n/a"), "", G8/C8 + D8) -> 0.34285714 | I8: =IF(MINIFS('Activity map'!$M:$M, 'Activity map'!$A:$A, A8, 'Activity map'!$H:$H, "=TRUE") = 0, "n/a", MINIFS('Activity map'!$M:$M, 'Activity map'!$A:$A, A8, 'Activity map'!$H:$H, "=TRUE")) -> n/a | J8: =IF(OR(ISBLANK(C8), I8 = "n/a"), "", I8/C8 + D8) | K8: =IF(MINIFS('Activity map'!$L:$L, 'Activity map'!$A:$A, A8, 'Activity map'!$H:$H, "=TRUE") = 0, "n/a", MINIFS('Activity map'!$L:$L, 'Activity map'!$A:$A, A8, 'Activity map'!$H:$H, "=TRUE")) -> n/a | L8: =IF(OR(ISBLANK(C8), K8 = "n/a"), "", K8/C8 + D8) | M8: =MINIFS('Activity map'!$C:$C, 'Activity map'!$A:$A, $A8, 'Activity map'!$H:$H, "=TRUE", 'Activity map'!$K:$K, MINIFS('Activity map'!$K:$K, 'Activity map'!$A:$A, $A8, 'Activity map'!$H:$H, "=TRUE")) -> 25630 | N8: =MINIFS('Activity map'!$C:$C, 'Activity map'!$A:$A, $A8, 'Activity map'!$H:$H, "=TRUE", 'Activity map'!$E:$E, $T8) -> 25442 | O8: =IF(MIN(F8,H8,J8,L8) = 0, "Done!", MIN(F8,H8,J8,L8) / 24) -> 0.00031667491 | P8: =IF($M8=0, "-", VLOOKUP($M8, 'List of log slots'!$A:$C, 2, FALSE)) -> Flamtaer bag | Q8: =IFERROR(__xludf.DUMMYFUNCTION("IF(ISERROR(FILTER('Activity map'!$C:$C, ('Activity map'!$A:$A=$A8)*('Activity map'!$F:$F=FALSE))), 0, COUNTA(UNIQUE(FILTER('Activity map'!$C:$C, ('Activity map'!$A:$A=$A8)*('Activity map'!$F:$F=FALSE)))))"),14.0) -> 14 | R8: =IFERROR(__xludf.DUMMYFUNCTION("IF(ISERROR(FILTER('Activity map'!$C:$C, 'Activity map'!$A:$A=$A8)), 0, COUNTA(UNIQUE(FILTER('Activity map'!$C:$C, 'Activity map'!$A:$A=$A8))))"),14.0) -> 14 | S8: =1 - Q8/R8 -> 0 | T8: =IFERROR(__xludf.DUMMYFUNCTION("IF(ISERROR(FILTER('Activity map'!$E:$E, ('Activity map'!$A:$A=$A8)*('Activity map'!$F:$F=FALSE))), ""-"", MIN(UNIQUE(FILTER('Activity map'!$E:$E, ('Activity map'!$A:$A=$A8)*('Activity map'!$F:$F=FALSE)))))"),2.0) -> 2 | U8: =IF($N8=0, "-", VLOOKUP($N8, 'List of log slots'!$A:$C, 2, FALSE)) -> Bronze locks
A9: 23 | B9: =VLOOKUP($A9, 'Completion rates'!$A:$E, 2, FALSE) -> Killing giant mole | C9: =IF(Notes!$E$27, VLOOKUP($A9, 'Completion rates'!$A:$E, 4, FALSE), VLOOKUP($A9, 'Completion rates'!$A:$E, 3, FALSE)) -> 125 | D9: =VLOOKUP($A9, 'Completion rates'!$A:$E, 5, FALSE) -> 0 | E9: =IF(SUMIFS('Activity map'!$O:$O, 'Activity map'!$A:$A, A9, 'Activity map'!$H:$H, "=TRUE") = 0, "n/a", 1/SUMIFS('Activity map'!$O:$O, 'Activity map'!$A:$A, A9, 'Activity map'!$H:$H, "=TRUE")) -> 307.20019 | F9: =IF(OR(ISBLANK(C9), E9 = "n/a"), "", E9/C9 + D9) -> 2.4576015 | G9: =IF(MINIFS('Activity map'!$N:$N, 'Activity map'!$A:$A, A9, 'Activity map'!$H:$H, "=TRUE") = 0, "n/a", MINIFS('Activity map'!$N:$N, 'Activity map'!$A:$A, A9, 'Activity map'!$H:$H, "=TRUE")) -> n/a | H9: =IF(OR(ISBLANK(C9), G9 = "n/a"), "", G9/C9 + D9) | I9: =IF(MINIFS('Activity map'!$M:$M, 'Activity map'!$A:$A, A9, 'Activity map'!$H:$H, "=TRUE") = 0, "n/a", MINIFS('Activity map'!$M:$M, 'Activity map'!$A:$A, A9, 'Activity map'!$H:$H, "=TRUE")) -> 1 | J9: =IF(OR(ISBLANK(C9), I9 = "n/a"), "", I9/C9 + D9) -> 0.008 | K9: =IF(MINIFS('Activity map'!$L:$L, 'Activity map'!$A:$A, A9, 'Activity map'!$H:$H, "=TRUE") = 0, "n/a", MINIFS('Activity map'!$L:$L, 'Activity map'!$A:$A, A9, 'Activity map'!$H:$H, "=TRUE")) -> n/a | L9: =IF(OR(ISBLANK(C9), K9 = "n/a"), "", K9/C9 + D9) | M9: =MINIFS('Activity map'!$C:$C, 'Activity map'!$A:$A, $A9, 'Activity map'!$H:$H, "=TRUE", 'Activity map'!$K:$K, MINIFS('Activity map'!$K:$K, 'Activity map'!$A:$A, $A9, 'Activity map'!$H:$H, "=TRUE")) -> 7416 | N9: =MINIFS('Activity map'!$C:$C, 'Activity map'!$A:$A, $A9, 'Activity map'!$H:$H, "=TRUE", 'Activity map'!$E:$E, $T9) -> 7416 | O9: =IF(MIN(F9,H9,J9,L9) = 0, "Done!", MIN(F9,H9,J9,L9) / 24) -> 0.00033333333 | P9: =IF($M9=0, "-", VLOOKUP($M9, 'List of log slots'!$A:$C, 2, FALSE)) -> Mole claw | Q9: =IFERROR(__xludf.DUMMYFUNCTION("IF(ISERROR(FILTER('Activity map'!$C:$C, ('Activity map'!$A:$A=$A9)*('Activity map'!$F:$F=FALSE))), 0, COUNTA(UNIQUE(FILTER('Activity map'!$C:$C, ('Activity map'!$A:$A=$A9)*('Activity map'!$F:$F=FALSE)))))"),7.0) -> 7 | R9: =IFERROR(__xludf.DUMMYFUNCTION("IF(ISERROR(FILTER('Activity map'!$C:$C, 'Activity map'!$A:$A=$A9)), 0, COUNTA(UNIQUE(FILTER('Activity map'!$C:$C, 'Activity map'!$A:$A=$A9))))"),7.0) -> 7 | S9: =1 - Q9/R9 -> 0 | T9: =IFERROR(__xludf.DUMMYFUNCTION("IF(ISERROR(FILTER('Activity map'!$E:$E, ('Activity map'!$A:$A=$A9)*('Activity map'!$F:$F=FALSE))), ""-"", MIN(UNIQUE(FILTER('Activity map'!$E:$E, ('Activity map'!$A:$A=$A9)*('Activity map'!$F:$F=FALSE)))))"),3.0) -> 3 | U9: =IF($N9=0, "-", VLOOKUP($N9, 'List of log slots'!$A:$C, 2, FALSE)) -> Mole claw
A10: 137 | B10: =VLOOKUP($A10, 'Completion rates'!$A:$E, 2, FALSE) -> Killing revenants (demon cyclops quads, skulled, skipping for task) | C10: =IF(Notes!$E$27, VLOOKUP($A10, 'Completion rates'!$A:$E, 4, FALSE), VLOOKUP($A10, 'Completion rates'!$A:$E, 3, FALSE)) -> 107 | D10: =VLOOKUP($A10, 'Completion rates'!$A:$E, 5, FALSE) -> 0 | E10: =IF(SUMIFS('Activity map'!$O:$O, 'Activity map'!$A:$A, A10, 'Activity map'!$H:$H, "=TRUE") = 0, "n/a", 1/SUMIFS('Activity map'!$O:$O, 'Activity map'!$A:$A, A10, 'Activity map'!$H:$H, "=TRUE")) -> 7.6450601 | F10: =IF(OR(ISBLANK(C10), E10 = "n/a"), "", E10/C10 + D10) -> 0.07144916 | G10: =IF(MINIFS('Activity map'!$N:$N, 'Activity map'!$A:$A, A10, 'Activity map'!$H:$H, "=TRUE") = 0, "n/a", MINIFS('Activity map'!$N:$N, 'Activity map'!$A:$A, A10, 'Activity map'!$H:$H, "=TRUE")) -> n/a | H10: =IF(OR(ISBLANK(C10), G10 = "n/a"), "", G10/C10 + D10) | I10: =IF(MINIFS('Activity map'!$M:$M, 'Activity map'!$A:$A, A10, 'Activity map'!$H:$H, "=TRUE") = 0, "n/a", MINIFS('Activity map'!$M:$M, 'Activity map'!$A:$A, A10, 'Activity map'!$H:$H, "=TRUE")) -> 1 | J10: =IF(OR(ISBLANK(C10), I10 = "n/a"), "", I10/C10 + D10) -> 0.0093457944 | K10: =IF(MINIFS('Activity map'!$L:$L, 'Activity map'!$A:$A, A10, 'Activity map'!$H:$H, "=TRUE") = 0, "n/a", MINIFS('Activity map'!$L:$L, 'Activity map'!$A:$A, A10, 'Activity map'!$H:$H, "=TRUE")) -> n/a | L10: =IF(OR(ISBLANK(C10), K10 = "n/a"), "", K10/C10 + D10) | M10: =MINIFS('Activity map'!$C:$C, 'Activity map'!$A:$A, $A10, 'Activity map'!$H:$H, "=TRUE", 'Activity map'!$K:$K, MINIFS('Activity map'!$K:$K, 'Activity map'!$A:$A, $A10, 'Activity map'!$H:$H, "=TRUE")) -> 21820 | N10: =MINIFS('Activity map'!$C:$C, 'Activity map'!$A:$A, $A10, 'Activity map'!$H:$H, "=TRUE", 'Activity map'!$E:$E, $T10) -> 21820 | O10: =IF(MIN(F10,H10,J10,L10) = 0, "Done!", MIN(F10,H10,J10,L10) / 24) -> 0.0003894081 | P10: =IF($M10=0, "-", VLOOKUP($M10, 'List of log slots'!$A:$C, 2, FALSE)) -> Revenant ether | Q10: =IFERROR(__xludf.DUMMYFUNCTION("IF(ISERROR(FILTER('Activity map'!$C:$C, ('Activity map'!$A:$A=$A10)*('Activity map'!$F:$F=FALSE))), 0, COUNTA(UNIQUE(FILTER('Activity map'!$C:$C, ('Activity map'!$A:$A=$A10)*('Activity map'!$F:$F=FALSE)))))"),14.0) -> 14 | R10: =IFERROR(__xludf.DUMMYFUNCTION("IF(ISERROR(FILTER('Activity map'!$C:$C, 'Activity map'!$A:$A=$A10)), 0, COUNTA(UNIQUE(FILTER('Activity map'!$C:$C, 'Activity map'!$A:$A=$A10))))"),14.0) -> 14 | S10: =1 - Q10/R10 -> 0 | T10: =IFERROR(__xludf.DUMMYFUNCTION("IF(ISERROR(FILTER('Activity map'!$E:$E, ('Activity map'!$A:$A=$A10)*('Activity map'!$F:$F=FALSE))), ""-"", MIN(UNIQUE(FILTER('Activity map'!$E:$E, ('Activity map'!$A:$A=$A10)*('Activity map'!$F:$F=FALSE)))))"),1.0) -> 1 | U10: =IF($N10=0, "-", VLOOKUP($N10, 'List of log slots'!$A:$C, 2, FALSE)) -> Revenant ether
A11: 47 | B11: =VLOOKUP($A11, 'Completion rates'!$A:$E, 2, FALSE) -> Killing shellbane gryphon (on task) | C11: =IF(Notes!$E$27, VLOOKUP($A11, 'Completion rates'!$A:$E, 4, FALSE), VLOOKUP($A11, 'Completion rates'!$A:$E, 3, FALSE)) -> 100 | D11: =VLOOKUP($A11, 'Completion rates'!$A:$E, 5, FALSE) -> 0 | E11: =IF(SUMIFS('Activity map'!$O:$O, 'Activity map'!$A:$A, A11, 'Activity map'!$H:$H, "=TRUE") = 0, "n/a", 1/SUMIFS('Activity map'!$O:$O, 'Activity map'!$A:$A, A11, 'Activity map'!$H:$H, "=TRUE")) -> 165.66844 | F11: =IF(OR(ISBLANK(C11), E11 = "n/a"), "", E11/C11 + D11) -> 1.6566844 | G11: =IF(MINIFS('Activity map'!$N:$N, 'Activity map'!$A:$A, A11, 'Activity map'!$H:$H, "=TRUE") = 0, "n/a", MINIFS('Activity map'!$N:$N, 'Activity map'!$A:$A, A11, 'Activity map'!$H:$H, "=TRUE")) -> n/a | H11: =IF(OR(ISBLANK(C11), G11 = "n/a"), "", G11/C11 + D11) | I11: =IF(MINIFS('Activity map'!$M:$M, 'Activity map'!$A:$A, A11, 'Activity map'!$H:$H, "=TRUE") = 0, "n/a", MINIFS('Activity map'!$M:$M, 'Activity map'!$A:$A, A11, 'Activity map'!$H:$H, "=TRUE")) -> 1 | J11: =IF(OR(ISBLANK(C11), I11 = "n/a"), "", I11/C11 + D11) -> 0.01 | K11: =IF(MINIFS('Activity map'!$L:$L, 'Activity map'!$A:$A, A11, 'Activity map'!$H:$H, "=TRUE") = 0, "n/a", MINIFS('Activity map'!$L:$L, 'Activity map'!$A:$A, A11, 'Activity map'!$H:$H, "=TRUE")) -> n/a | L11: =IF(OR(ISBLANK(C11), K11 = "n/a"), "", K11/C11 + D11) | M11: =MINIFS('Activity map'!$C:$C, 'Activity map'!$A:$A, $A11, 'Activity map'!$H:$H, "=TRUE", 'Activity map'!$K:$K, MINIFS('Activity map'!$K:$K, 'Activity map'!$A:$A, $A11, 'Activity map'!$H:$H, "=TRUE")) -> 31235 | N11: =MINIFS('Activity map'!$C:$C, 'Activity map'!$A:$A, $A11, 'Activity map'!$H:$H, "=TRUE", 'Activity map'!$E:$E, $T11) -> 10976 | O11: =IF(MIN(F11,H11,J11,L11) = 0, "Done!", MIN(F11,H11,J11,L11) / 24) -> 0.00041666667 | P11: =IF($M11=0, "-", VLOOKUP($M11, 'List of log slots'!$A:$C, 2, FALSE)) -> Gryphon feather | Q11: =IFERROR(__xludf.DUMMYFUNCTION("IF(ISERROR(FILTER('Activity map'!$C:$C, ('Activity map'!$A:$A=$A11)*('Activity map'!$F:$F=FALSE))), 0, COUNTA(UNIQUE(FILTER('Activity map'!$C:$C, ('Activity map'!$A:$A=$A11)*('Activity map'!$F:$F=FALSE)))))"),8.0) -> 8 | R11: =IFERROR(__xludf.DUMMYFUNCTION("IF(ISERROR(FILTER('Activity map'!$C:$C, 'Activity map'!$A:$A=$A11)), 0, COUNTA(UNIQUE(FILTER('Activity map'!$C:$C, 'Activity map'!$A:$A=$A11))))"),8.0) -> 8 | S11: =1 - Q11/R11 -> 0 | T11: =IFERROR(__xludf.DUMMYFUNCTION("IF(ISERROR(FILTER('Activity map'!$E:$E, ('Activity map'!$A:$A=$A11)*('Activity map'!$F:$F=FALSE))), ""-"", MIN(UNIQUE(FILTER('Activity map'!$E:$E, ('Activity map'!$A:$A=$A11)*('Activity map'!$F:$F=FALSE)))))"),3.0) -> 3 | U11: =IF($N11=0, "-", VLOOKUP($N11, 'List of log slots'!$A:$C, 2, FALSE)) -> Long bone
A12: 154 | B12: =VLOOKUP($A12, 'Completion rates'!$A:$E, 2, FALSE) -> Killing soldiers in the shayzien combat ring | C12: =IF(Notes!$E$27, VLOOKUP($A12, 'Completion rates'!$A:$E, 4, FALSE), VLOOKUP($A12, 'Completion rates'!$A:$E, 3, FALSE)) -> 100 | D12: =VLOOKUP($A12, 'Completion rates'!$A:$E, 5, FALSE) -> 0 | E12: =IF(SUMIFS('Activity map'!$O:$O, 'Activity map'!$A:$A, A12, 'Activity map'!$H:$H, "=TRUE") = 0, "n/a", 1/SUMIFS('Activity map'!$O:$O, 'Activity map'!$A:$A, A12, 'Activity map'!$H:$H, "=TRUE")) -> n/a | F12: =IF(OR(ISBLANK(C12), E12 = "n/a"), "", E12/C12 + D12) | G12: =IF(MINIFS('Activity map'!$N:$N, 'Activity map'!$A:$A, A12, 'Activity map'!$H:$H, "=TRUE") = 0, "n/a", MINIFS('Activity map'!$N:$N, 'Activity map'!$A:$A, A12, 'Activity map'!$H:$H, "=TRUE")) -> n/a | H12: =IF(OR(ISBLANK(C12), G12 = "n/a"), "", G12/C12 + D12) | I12: =IF(MINIFS('Activity map'!$M:$M, 'Activity map'!$A:$A, A12, 'Activity map'!$H:$H, "=TRUE") = 0, "n/a", MINIFS('Activity map'!$M:$M, 'Activity map'!$A:$A, A12, 'Activity map'!$H:$H, "=TRUE")) -> n/a | J12: =IF(OR(ISBLANK(C12), I12 = "n/a"), "", I12/C12 + D12) | K12: =IF(MINIFS('Activity map'!$L:$L, 'Activity map'!$A:$A, A12, 'Activity map'!$H:$H, "=TRUE") = 0, "n/a", MINIFS('Activity map'!$L:$L, 'Activity map'!$A:$A, A12, 'Activity map'!$H:$H, "=TRUE")) -> 1 | L12: =IF(OR(ISBLANK(C12), K12 = "n/a"), "", K12/C12 + D12) -> 0.01 | M12: =MINIFS('Activity map'!$C:$C, 'Activity map'!$A:$A, $A12, 'Activity map'!$H:$H, "=TRUE", 'Activity map'!$K:$K, MINIFS('Activity map'!$K:$K, 'Activity map'!$A:$A, $A12, 'Activity map'!$H:$H, "=TRUE")) -> 13357 | N12: =MINIFS('Activity map'!$C:$C, 'Activity map'!$A:$A, $A12, 'Activity map'!$H:$H, "=TRUE", 'Activity map'!$E:$E, $T12) -> 13357 | O12: =IF(MIN(F12,H12,J12,L12) = 0, "Done!", MIN(F12,H12,J12,L12) / 24) -> 0.00041666667 | P12: =IF($M12=0, "-", VLOOKUP($M12, 'List of log slots'!$A:$C, 2, FALSE)) -> Shayzien gloves (1) | Q12: =IFERROR(__xludf.DUMMYFUNCTION("IF(ISERROR(FILTER('Activity map'!$C:$C, ('Activity map'!$A:$A=$A12)*('Activity map'!$F:$F=FALSE))), 0, COUNTA(UNIQUE(FILTER('Activity map'!$C:$C, ('Activity map'!$A:$A=$A12)*('Activity map'!$F:$F=FALSE)))))"),25.0) -> 25 | R12: =IFERROR(__xludf.DUMMYFUNCTION("IF(ISERROR(FILTER('Activity map'!$C:$C, 'Activity map'!$A:$A=$A12)), 0, COUNTA(UNIQUE(FILTER('Activity map'!$C:$C, 'Activity map'!$A:$A=$A12))))"),25.0) -> 25 | S12: =1 - Q12/R12 -> 0 | T12: =IFERROR(__xludf.DUMMYFUNCTION("IF(ISERROR(FILTER('Activity map'!$E:$E, ('Activity map'!$A:$A=$A12)*('Activity map'!$F:$F=FALSE))), ""-"", MIN(UNIQUE(FILTER('Activity map'!$E:$E, ('Activity map'!$A:$A=$A12)*('Activity map'!$F:$F=FALSE)))))"),1.0) -> 1 | U12: =IF($N12=0, "-", VLOOKUP($N12, 'List of log slots'!$A:$C, 2, FALSE)) -> Shayzien gloves (1)
A13: 240 | B13: =VLOOKUP($A13, 'Completion rates'!$A:$E, 2, FALSE) -> Killing underwater crabs (level 23) | C13: =IF(Notes!$E$27, VLOOKUP($A13, 'Completion rates'!$A:$E, 4, FALSE), VLOOKUP($A13, 'Completion rates'!$A:$E, 3, FALSE)) -> 400 | D13: =VLOOKUP($A13, 'Completion rates'!$A:$E, 5, FALSE) -> 0 | E13: =IF(SUMIFS('Activity map'!$O:$O, 'Activity map'!$A:$A, A13, 'Activity map'!$H:$H, "=TRUE") = 0, "n/a", 1/SUMIFS('Activity map'!$O:$O, 'Activity map'!$A:$A, A13, 'Activity map'!$H:$H, "=TRUE")) -> 4 | F13: =IF(OR(ISBLANK(C13), E13 = "n/a"), "", E13/C13 + D13) -> 0.01 | G13: =IF(MINIFS('Activity map'!$N:$N, 'Activity map'!$A:$A, A13, 'Activity map'!$H:$H, "=TRUE") = 0, "n/a", MINIFS('Activity map'!$N:$N, 'Activity map'!$A:$A, A13, 'Activity map'!$H:$H, "=TRUE")) -> n/a | H13: =IF(OR(ISBLANK(C13), G13 = "n/a"), "", G13/C13 + D13) | I13: =IF(MINIFS('Activity map'!$M:$M, 'Activity map'!$A:$A, A13, 'Activity map'!$H:$H, "=TRUE") = 0, "n/a", MINIFS('Activity map'!$M:$M, 'Activity map'!$A:$A, A13, 'Activity map'!$H:$H, "=TRUE")) -> n/a | J13: =IF(OR(ISBLANK(C13), I13 = "n/a"), "", I13/C13 + D13) | K13: =IF(MINIFS('Activity map'!$L:$L, 'Activity map'!$A:$A, A13, 'Activity map'!$H:$H, "=TRUE") = 0, "n/a", MINIFS('Activity map'!$L:$L, 'Activity map'!$A:$A, A13, 'Activity map'!$H:$H, "=TRUE")) -> n/a | L13: =IF(OR(ISBLANK(C13), K13 = "n/a"), "", K13/C13 + D13) | M13: =MINIFS('Activity map'!$C:$C, 'Activity map'!$A:$A, $A13, 'Activity map'!$H:$H, "=TRUE", 'Activity map'!$K:$K, MINIFS('Activity map'!$K:$K, 'Activity map'!$A:$A, $A13, 'Activity map'!$H:$H, "=TRUE")) -> 7536 | N13: =MINIFS('Activity map'!$C:$C, 'Activity map'!$A:$A, $A13, 'Activity map'!$H:$H, "=TRUE", 'Activity map'!$E:$E, $T13) -> 7536 | O13: =IF(MIN(F13,H13,J13,L13) = 0, "Done!", MIN(F13,H13,J13,L13) / 24) -> 0.00041666667 | P13: =IF($M13=0, "-", VLOOKUP($M13, 'List of log slots'!$A:$C, 2, FALSE)) -> Fresh crab claw | Q13: =IFERROR(__xludf.DUMMYFUNCTION("IF(ISERROR(FILTER('Activity map'!$C:$C, ('Activity map'!$A:$A=$A13)*('Activity map'!$F:$F=FALSE))), 0, COUNTA(UNIQUE(FILTER('Activity map'!$C:$C, ('Activity map'!$A:$A=$A13)*('Activity map'!$F:$F=FALSE)))))"),2.0) -> 2 | R13: =IFERROR(__xludf.DUMMYFUNCTION("IF(ISERROR(FILTER('Activity map'!$C:$C, 'Activity map'!$A:$A=$A13)), 0, COUNTA(UNIQUE(FILTER('Activity map'!$C:$C, 'Activity map'!$A:$A=$A13))))"),2.0) -> 2 | S13: =1 - Q13/R13 -> 0 | T13: =IFERROR(__xludf.DUMMYFUNCTION("IF(ISERROR(FILTER('Activity map'!$E:$E, ('Activity map'!$A:$A=$A13)*('Activity map'!$F:$F=FALSE))), ""-"", MIN(UNIQUE(FILTER('Activity map'!$E:$E, ('Activity map'!$A:$A=$A13)*('Activity map'!$F:$F=FALSE)))))"),1.0) -> 1 | U13: =IF($N13=0, "-", VLOOKUP($N13, 'List of log slots'!$A:$C, 2, FALSE)) -> Fresh crab claw
A14: 25 | B14: =VLOOKUP($A14, 'Completion rates'!$A:$E, 2, FALSE) -> Harvesting hespori | C14: =IF(Notes!$E$27, VLOOKUP($A14, 'Completion rates'!$A:$E, 4, FALSE), VLOOKUP($A14, 'Completion rates'!$A:$E, 3, FALSE)) -> 95 | D14: =VLOOKUP($A14, 'Completion rates'!$A:$E, 5, FALSE) -> 0 | E14: =IF(SUMIFS('Activity map'!$O:$O, 'Activity map'!$A:$A, A14, 'Activity map'!$H:$H, "=TRUE") = 0, "n/a", 1/SUMIFS('Activity map'!$O:$O, 'Activity map'!$A:$A, A14, 'Activity map'!$H:$H, "=TRUE")) -> 0.97222222 | F14: =IF(OR(ISBLANK(C14), E14 = "n/a"), "", E14/C14 + D14) -> 0.010233918 | G14: =IF(MINIFS('Activity map'!$N:$N, 'Activity map'!$A:$A, A14, 'Activity map'!$H:$H, "=TRUE") = 0, "n/a", MINIFS('Activity map'!$N:$N, 'Activity map'!$A:$A, A14, 'Activity map'!$H:$H, "=TRUE")) -> n/a | H14: =IF(OR(ISBLANK(C14), G14 = "n/a"), "", G14/C14 + D14) | I14: =IF(MINIFS('Activity map'!$M:$M, 'Activity map'!$A:$A, A14, 'Activity map'!$H:$H, "=TRUE") = 0, "n/a", MINIFS('Activity map'!$M:$M, 'Activity map'!$A:$A, A14, 'Activity map'!$H:$H, "=TRUE")) -> n/a | J14: =IF(OR(ISBLANK(C14), I14 = "n/a"), "", I14/C14 + D14) | K14: =IF(MINIFS('Activity map'!$L:$L, 'Activity map'!$A:$A, A14, 'Activity map'!$H:$H, "=TRUE") = 0, "n/a", MINIFS('Activity map'!$L:$L, 'Activity map'!$A:$A, A14, 'Activity map'!$H:$H, "=TRUE")) -> n/a | L14: =IF(OR(ISBLANK(C14), K14 = "n/a"), "", K14/C14 + D14) | M14: =MINIFS('Activity map'!$C:$C, 'Activity map'!$A:$A, $A14, 'Activity map'!$H:$H, "=TRUE", 'Activity map'!$K:$K, MINIFS('Activity map'!$K:$K, 'Activity map'!$A:$A, $A14, 'Activity map'!$H:$H, "=TRUE")) -> 22881 | N14: =MINIFS('Activity map'!$C:$C, 'Activity map'!$A:$A, $A14, 'Activity map'!$H:$H, "=TRUE", 'Activity map'!$E:$E, $T14) -> 22881 | O14: =IF(MIN(F14,H14,J14,L14) = 0, "Done!", MIN(F14,H14,J14,L14) / 24) -> 0.00042641326 | P14: =IF($M14=0, "-", VLOOKUP($M14, 'List of log slots'!$A:$C, 2, FALSE)) -> Attas seed | Q14: =IFERROR(__xludf.DUMMYFUNCTION("IF(ISERROR(FILTER('Activity map'!$C:$C, ('Activity map'!$A:$A=$A14)*('Activity map'!$F:$F=FALSE))), 0, COUNTA(UNIQUE(FILTER('Activity map'!$C:$C, ('Activity map'!$A:$A=$A14)*('Activity map'!$F:$F=FALSE)))))"),4.0) -> 4 | R14: =IFERROR(__xludf.DUMMYFUNCTION("IF(ISERROR(FILTER('Activity map'!$C:$C, 'Activity map'!$A:$A=$A14)), 0, COUNTA(UNIQUE(FILTER('Activity map'!$C:$C, 'Activity map'!$A:$A=$A14))))"),4.0) -> 4 | S14: =1 - Q14/R14 -> 0 | T14: =IFERROR(__xludf.DUMMYFUNCTION("IF(ISERROR(FILTER('Activity map'!$E:$E, ('Activity map'!$A:$A=$A14)*('Activity map'!$F:$F=FALSE))), ""-"", MIN(UNIQUE(FILTER('Activity map'!$E:$E, ('Activity map'!$A:$A=$A14)*('Activity map'!$F:$F=FALSE)))))"),3.0) -> 3 | U14: =IF($N14=0, "-", VLOOKUP($N14, 'List of log slots'!$A:$C, 2, FALSE)) -> Attas seed
A15: 3 | B15: =VLOOKUP($A15, 'Completion rates'!$A:$E, 2, FALSE) -> Killing amoxliatl | C15: =IF(Notes!$E$27, VLOOKUP($A15, 'Completion rates'!$A:$E, 4, FALSE), VLOOKUP($A15, 'Completion rates'!$A:$E, 3, FALSE)) -> 85 | D15: =VLOOKUP($A15, 'Completion rates'!$A:$E, 5, FALSE) -> 0 | E15: =IF(SUMIFS('Activity map'!$O:$O, 'Activity map'!$A:$A, A15, 'Activity map'!$H:$H, "=TRUE") = 0, "n/a", 1/SUMIFS('Activity map'!$O:$O, 'Activity map'!$A:$A, A15, 'Activity map'!$H:$H, "=TRUE")) -> 11.785975 | F15: =IF(OR(ISBLANK(C15), E15 = "n/a"), "", E15/C15 + D15) -> 0.13865853 | G15: =IF(MINIFS('Activity map'!$N:$N, 'Activity map'!$A:$A, A15, 'Activity map'!$H:$H, "=TRUE") = 0, "n/a", MINIFS('Activity map'!$N:$N, 'Activity map'!$A:$A, A15, 'Activity map'!$H:$H, "=TRUE")) -> n/a | H15: =IF(OR(ISBLANK(C15), G15 = "n/a"), "", G15/C15 + D15) | I15: =IF(MINIFS('Activity map'!$M:$M, 'Activity map'!$A:$A, A15, 'Activity map'!$H:$H, "=TRUE") = 0, "n/a", MINIFS('Activity map'!$M:$M, 'Activity map'!$A:$A, A15, 'Activity map'!$H:$H, "=TRUE")) -> 1 | J15: =IF(OR(ISBLANK(C15), I15 = "n/a"), "", I15/C15 + D15) -> 0.011764706 | K15: =IF(MINIFS('Activity map'!$L:$L, 'Activity map'!$A:$A, A15, 'Activity map'!$H:$H, "=TRUE") = 0, "n/a", MINIFS('Activity map'!$L:$L, 'Activity map'!$A:$A, A15, 'Activity map'!$H:$H, "=TRUE")) -> n/a | L15: =IF(OR(ISBLANK(C15), K15 = "n/a"), "", K15/C15 + D15) | M15: =MINIFS('Activity map'!$C:$C, 'Activity map'!$A:$A, $A15, 'Activity map'!$H:$H, "=TRUE", 'Activity map'!$K:$K, MINIFS('Activity map'!$K:$K, 'Activity map'!$A:$A, $A15, 'Activity map'!$H:$H, "=TRUE")) -> 29895 | N15: =MINIFS('Activity map'!$C:$C, 'Activity map'!$A:$A, $A15, 'Activity map'!$H:$H, "=TRUE", 'Activity map'!$E:$E, $T15) -> 29895 | O15: =IF(MIN(F15,H15,J15,L15) = 0, "Done!", MIN(F15,H15,J15,L15) / 24) -> 0.00049019608 | P15: =IF($M15=0, "-", VLOOKUP($M15, 'List of log slots'!$A:$C, 2, FALSE)) -> Frozen tear | Q15: =IFERROR(__xludf.DUMMYFUNCTION("IF(ISERROR(FILTER('Activity map'!$C:$C, ('Activity map'!$A:$A=$A15)*('Activity map'!$F:$F=FALSE))), 0, COUNTA(UNIQUE(FILTER('Activity map'!$C:$C, ('Activity map'!$A:$A=$A15)*('Activity map'!$F:$F=FALSE)))))"),7.0) -> 7 | R15: =IFERROR(__xludf.DUMMYFUNCTION("IF(ISERROR(FILTER('Activity map'!$C:$C, 'Activity map'!$A:$A=$A15)), 0, COUNTA(UNIQUE(FILTER('Activity map'!$C:$C, 'Activity map'!$A:$A=$A15))))"),7.0) -> 7 | S15: =1 - Q15/R15 -> 0 | T15: =IFERROR(__xludf.DUMMYFUNCTION("IF(ISERROR(FILTER('Activity map'!$E:$E, ('Activity map'!$A:$A=$A15)*('Activity map'!$F:$F=FALSE))), ""-"", MIN(UNIQUE(FILTER('Activity map'!$E:$E, ('Activity map'!$A:$A=$A15)*('Activity map'!$F:$F=FALSE)))))"),3.0) -> 3 | U15: =IF($N15=0, "-", VLOOKUP($N15, 'List of log slots'!$A:$C, 2, FALSE)) -> Frozen tear
A16: 78 | B16: =VLOOKUP($A16, 'Completion rates'!$A:$E, 2, FALSE) -> Getting brimhaven vouchers | C16: =IF(Notes!$E$27, VLOOKUP($A16, 'Completion rates'!$A:$E, 4, FALSE), VLOOKUP($A16, 'Completion rates'!$A:$E, 3, FALSE)) -> 66 | D16: =VLOOKUP($A16, 'Completion rates'!$A:$E, 5, FALSE) -> 0 | E16: =IF(SUMIFS('Activity map'!$O:$O, 'Activity map'!$A:$A, A16, 'Activity map'!$H:$H, "=TRUE") = 0, "n/a", 1/SUMIFS('Activity map'!$O:$O, 'Activity map'!$A:$A, A16, 'Activity map'!$H:$H, "=TRUE")) -> 1 | F16: =IF(OR(ISBLANK(C16), E16 = "n/a"), "", E16/C16 + D16) -> 0.015151515 | G16: =IF(MINIFS('Activity map'!$N:$N, 'Activity map'!$A:$A, A16, 'Activity map'!$H:$H, "=TRUE") = 0, "n/a", MINIFS('Activity map'!$N:$N, 'Activity map'!$A:$A, A16, 'Activity map'!$H:$H, "=TRUE")) -> n/a | H16: =IF(OR(ISBLANK(C16), G16 = "n/a"), "", G16/C16 + D16) | I16: =IF(MINIFS('Activity map'!$M:$M, 'Activity map'!$A:$A, A16, 'Activity map'!$H:$H, "=TRUE") = 0, "n/a", MINIFS('Activity map'!$M:$M, 'Activity map'!$A:$A, A16, 'Activity map'!$H:$H, "=TRUE")) -> 1 | J16: =IF(OR(ISBLANK(C16), I16 = "n/a"), "", I16/C16 + D16) -> 0.015151515 | K16: =IF(MINIFS('Activity map'!$L:$L, 'Activity map'!$A:$A, A16, 'Activity map'!$H:$H, "=TRUE") = 0, "n/a", MINIFS('Activity map'!$L:$L, 'Activity map'!$A:$A, A16, 'Activity map'!$H:$H, "=TRUE")) -> 250 | L16: =IF(OR(ISBLANK(C16), K16 = "n/a"), "", K16/C16 + D16) -> 3.7878788 | M16: =MINIFS('Activity map'!$C:$C, 'Activity map'!$A:$A, $A16, 'Activity map'!$H:$H, "=TRUE", 'Activity map'!$K:$K, MINIFS('Activity map'!$K:$K, 'Activity map'!$A:$A, $A16, 'Activity map'!$H:$H, "=TRUE")) -> 2996 | N16: =MINIFS('Activity map'!$C:$C, 'Activity map'!$A:$A, $A16, 'Activity map'!$H:$H, "=TRUE", 'Activity map'!$E:$E, $T16) -> 2996 | O16: =IF(MIN(F16,H16,J16,L16) = 0, "Done!", MIN(F16,H16,J16,L16) / 24) -> 0.00063131313 | P16: =IF($M16=0, "-", VLOOKUP($M16, 'List of log slots'!$A:$C, 2, FALSE)) -> Agility arena ticket | Q16: =IFERROR(__xludf.DUMMYFUNCTION("IF(ISERROR(FILTER('Activity map'!$C:$C, ('Activity map'!$A:$A=$A16)*('Activity map'!$F:$F=FALSE))), 0, COUNTA(UNIQUE(FILTER('Activity map'!$C:$C, ('Activity map'!$A:$A=$A16)*('Activity map'!$F:$F=FALSE)))))"),9.0) -> 9 | R16: =IFERROR(__xludf.DUMMYFUNCTION("IF(ISERROR(FILTER('Activity map'!$C:$C, 'Activity map'!$A:$A=$A16)), 0, COUNTA(UNIQUE(FILTER('Activity map'!$C:$C, 'Activity map'!$A:$A=$A16))))"),9.0) -> 9 | S16: =1 - Q16/R16 -> 0 | T16: =IFERROR(__xludf.DUMMYFUNCTION("IF(ISERROR(FILTER('Activity map'!$E:$E, ('Activity map'!$A:$A=$A16)*('Activity map'!$F:$F=FALSE))), ""-"", MIN(UNIQUE(FILTER('Activity map'!$E:$E, ('Activity map'!$A:$A=$A16)*('Activity map'!$F:$F=FALSE)))))"),1.0) -> 1 | U16: =IF($N16=0, "-", VLOOKUP($N16, 'List of log slots'!$A:$C, 2, FALSE)) -> Agility arena ticket
A17: 42 | B17: =VLOOKUP($A17, 'Completion rates'!$A:$E, 2, FALSE) -> Looting branda, the fire queen (royal titans) | C17: =IF(Notes!$E$27, VLOOKUP($A17, 'Completion rates'!$A:$E, 4, FALSE), VLOOKUP($A17, 'Completion rates'!$A:$E, 3, FALSE)) -> 60 | D17: =VLOOKUP($A17, 'Completion rates'!$A:$E, 5, FALSE) -> 0 | E17: =IF(SUMIFS('Activity map'!$O:$O, 'Activity map'!$A:$A, A17, 'Activity map'!$H:$H, "=TRUE") = 0, "n/a", 1/SUMIFS('Activity map'!$O:$O, 'Activity map'!$A:$A, A17, 'Activity map'!$H:$H, "=TRUE")) -> 5.7859209 | F17: =IF(OR(ISBLANK(C17), E17 = "n/a"), "", E17/C17 + D17) -> 0.096432015 | G17: =IF(MINIFS('Activity map'!$N:$N, 'Activity map'!$A:$A, A17, 'Activity map'!$H:$H, "=TRUE") = 0, "n/a", MINIFS('Activity map'!$N:$N, 'Activity map'!$A:$A, A17, 'Activity map'!$H:$H, "=TRUE")) -> 1500 | H17: =IF(OR(ISBLANK(C17), G17 = "n/a"), "", G17/C17 + D17) -> 25 | I17: =IF(MINIFS('Activity map'!$M:$M, 'Activity map'!$A:$A, A17, 'Activity map'!$H:$H, "=TRUE") = 0, "n/a", MINIFS('Activity map'!$M:$M, 'Activity map'!$A:$A, A17, 'Activity map'!$H:$H, "=TRUE")) -> n/a | J17: =IF(OR(ISBLANK(C17), I17 = "n/a"), "", I17/C17 + D17) | K17: =IF(MINIFS('Activity map'!$L:$L, 'Activity map'!$A:$A, A17, 'Activity map'!$H:$H, "=TRUE") = 0, "n/a", MINIFS('Activity map'!$L:$L, 'Activity map'!$A:$A, A17, 'Activity map'!$H:$H, "=TRUE")) -> 1 | L17: =IF(OR(ISBLANK(C17), K17 = "n/a"), "", K17/C17 + D17) -> 0.016666667 | M17: =MINIFS('Activity map'!$C:$C, 'Activity map'!$A:$A, $A17, 'Activity map'!$H:$H, "=TRUE", 'Activity map'!$K:$K, MINIFS('Activity map'!$K:$K, 'Activity map'!$A:$A, $A17, 'Activity map'!$H:$H, "=TRUE")) -> 30640 | N17: =MINIFS('Activity map'!$C:$C, 'Activity map'!$A:$A, $A17, 'Activity map'!$H:$H, "=TRUE", 'Activity map'!$E:$E, $T17) -> 30637 | O17: =IF(MIN(F17,H17,J17,L17) = 0, "Done!", MIN(F17,H17,J17,L17) / 24) -> 0.00069444444 | P17: =IF($M17=0, "-", VLOOKUP($M17, 'List of log slots'!$A:$C, 2, FALSE)) -> Desiccated page | Q17: =IFERROR(__xludf.DUMMYFUNCTION("IF(ISERROR(FILTER('Activity map'!$C:$C, ('Activity map'!$A:$A=$A17)*('Activity map'!$F:$F=FALSE))), 0, COUNTA(UNIQUE(FILTER('Activity map'!$C:$C, ('Activity map'!$A:$A=$A17)*('Activity map'!$F:$F=FALSE)))))"),5.0) -> 5 | R17: =IFERROR(__xludf.DUMMYFUNCTION("IF(ISERROR(FILTER('Activity map'!$C:$C, 'Activity map'!$A:$A=$A17)), 0, COUNTA(UNIQUE(FILTER('Activity map'!$C:$C, 'Activity map'!$A:$A=$A17))))"),5.0) -> 5 | S17: =1 - Q17/R17 -> 0 | T17: =IFERROR(__xludf.DUMMYFUNCTION("IF(ISERROR(FILTER('Activity map'!$E:$E, ('Activity map'!$A:$A=$A17)*('Activity map'!$F:$F=FALSE))), ""-"", MIN(UNIQUE(FILTER('Activity map'!$E:$E, ('Activity map'!$A:$A=$A17)*('Activity map'!$F:$F=FALSE)))))"),3.0) -> 3 | U17: =IF($N17=0, "-", VLOOKUP($N17, 'List of log slots'!$A:$C, 2, FALSE)) -> Giantsoul amulet (uncharged)
A18: 43 | B18: =VLOOKUP($A18, 'Completion rates'!$A:$E, 2, FALSE) -> Looting eldric, the ice king (royal titans) | C18: =IF(Notes!$E$27, VLOOKUP($A18, 'Completion rates'!$A:$E, 4, FALSE), VLOOKUP($A18, 'Completion rates'!$A:$E, 3, FALSE)) -> 60 | D18: =VLOOKUP($A18, 'Completion rates'!$A:$E, 5, FALSE) -> 0 | E18: =IF(SUMIFS('Activity map'!$O:$O, 'Activity map'!$A:$A, A18, 'Activity map'!$H:$H, "=TRUE") = 0, "n/a", 1/SUMIFS('Activity map'!$O:$O, 'Activity map'!$A:$A, A18, 'Activity map'!$H:$H, "=TRUE")) -> 5.7859209 | F18: =IF(OR(ISBLANK(C18), E18 = "n/a"), "", E18/C18 + D18) -> 0.096432015 | G18: =IF(MINIFS('Activity map'!$N:$N, 'Activity map'!$A:$A, A18, 'Activity map'!$H:$H, "=TRUE") = 0, "n/a", MINIFS('Activity map'!$N:$N, 'Activity map'!$A:$A, A18, 'Activity map'!$H:$H, "=TRUE")) -> 1500 | H18: =IF(OR(ISBLANK(C18), G18 = "n/a"), "", G18/C18 + D18) -> 25 | I18: =IF(MINIFS('Activity map'!$M:$M, 'Activity map'!$A:$A, A18, 'Activity map'!$H:$H, "=TRUE") = 0, "n/a", MINIFS('Activity map'!$M:$M, 'Activity map'!$A:$A, A18, 'Activity map'!$H:$H, "=TRUE")) -> n/a | J18: =IF(OR(ISBLANK(C18), I18 = "n/a"), "", I18/C18 + D18) | K18: =IF(MINIFS('Activity map'!$L:$L, 'Activity map'!$A:$A, A18, 'Activity map'!$H:$H, "=TRUE") = 0, "n/a", MINIFS('Activity map'!$L:$L, 'Activity map'!$A:$A, A18, 'Activity map'!$H:$H, "=TRUE")) -> 1 | L18: =IF(OR(ISBLANK(C18), K18 = "n/a"), "", K18/C18 + D18) -> 0.016666667 | M18: =MINIFS('Activity map'!$C:$C, 'Activity map'!$A:$A, $A18, 'Activity map'!$H:$H, "=TRUE", 'Activity map'!$K:$K, MINIFS('Activity map'!$K:$K, 'Activity map'!$A:$A, $A18, 'Activity map'!$H:$H, "=TRUE")) -> 30640 | N18: =MINIFS('Activity map'!$C:$C, 'Activity map'!$A:$A, $A18, 'Activity map'!$H:$H, "=TRUE", 'Activity map'!$E:$E, $T18) -> 30637 | O18: =IF(MIN(F18,H18,J18,L18) = 0, "Done!", MIN(F18,H18,J18,L18) / 24) -> 0.00069444444 | P18: =IF($M18=0, "-", VLOOKUP($M18, 'List of log slots'!$A:$C, 2, FALSE)) -> Desiccated page | Q18: =IFERROR(__xludf.DUMMYFUNCTION("IF(ISERROR(FILTER('Activity map'!$C:$C, ('Activity map'!$A:$A=$A18)*('Activity map'!$F:$F=FALSE))), 0, COUNTA(UNIQUE(FILTER('Activity map'!$C:$C, ('Activity map'!$A:$A=$A18)*('Activity map'!$F:$F=FALSE)))))"),5.0) -> 5 | R18: =IFERROR(__xludf.DUMMYFUNCTION("IF(ISERROR(FILTER('Activity map'!$C:$C, 'Activity map'!$A:$A=$A18)), 0, COUNTA(UNIQUE(FILTER('Activity map'!$C:$C, 'Activity map'!$A:$A=$A18))))"),5.0) -> 5 | S18: =1 - Q18/R18 -> 0 | T18: =IFERROR(__xludf.DUMMYFUNCTION("IF(ISERROR(FILTER('Activity map'!$E:$E, ('Activity map'!$A:$A=$A18)*('Activity map'!$F:$F=FALSE))), ""-"", MIN(UNIQUE(FILTER('Activity map'!$E:$E, ('Activity map'!$A:$A=$A18)*('Activity map'!$F:$F=FALSE)))))"),3.0) -> 3 | U18: =IF($N18=0, "-", VLOOKUP($N18, 'List of log slots'!$A:$C, 2, FALSE)) -> Giantsoul amulet (uncharged)
A19: 98 | B19: =VLOOKUP($A19, 'Completion rates'!$A:$E, 2, FALSE) -> Earning pieces of eight (trouble brewing) | C19: =IF(Notes!$E$27, VLOOKUP($A19, 'Completion rates'!$A:$E, 4, FALSE), VLOOKUP($A19, 'Completion rates'!$A:$E, 3, FALSE)) -> 1200 | D19: =VLOOKUP($A19, 'Completion rates'!$A:$E, 5, FALSE) -> 0 | E19: =IF(SUMIFS('Activity map'!$O:$O, 'Activity map'!$A:$A, A19, 'Activity map'!$H:$H, "=TRUE") = 0, "n/a", 1/SUMIFS('Activity map'!$O:$O, 'Activity map'!$A:$A, A19, 'Activity map'!$H:$H, "=TRUE")) -> n/a | F19: =IF(OR(ISBLANK(C19), E19 = "n/a"), "", E19/C19 + D19) | G19: =IF(MINIFS('Activity map'!$N:$N, 'Activity map'!$A:$A, A19, 'Activity map'!$H:$H, "=TRUE") = 0, "n/a", MINIFS('Activity map'!$N:$N, 'Activity map'!$A:$A, A19, 'Activity map'!$H:$H, "=TRUE")) -> n/a | H19: =IF(OR(ISBLANK(C19), G19 = "n/a"), "", G19/C19 + D19) | I19: =IF(MINIFS('Activity map'!$M:$M, 'Activity map'!$A:$A, A19, 'Activity map'!$H:$H, "=TRUE") = 0, "n/a", MINIFS('Activity map'!$M:$M, 'Activity map'!$A:$A, A19, 'Activity map'!$H:$H, "=TRUE")) -> n/a | J19: =IF(OR(ISBLANK(C19), I19 = "n/a"), "", I19/C19 + D19) | K19: =IF(MINIFS('Activity map'!$L:$L, 'Activity map'!$A:$A, A19, 'Activity map'!$H:$H, "=TRUE") = 0, "n/a", MINIFS('Activity map'!$L:$L, 'Activity map'!$A:$A, A19, 'Activity map'!$H:$H, "=TRUE")) -> 20 | L19: =IF(OR(ISBLANK(C19), K19 = "n/a"), "", K19/C19 + D19) -> 0.016666667 | M19: =MINIFS('Activity map'!$C:$C, 'Activity map'!$A:$A, $A19, 'Activity map'!$H:$H, "=TRUE", 'Activity map'!$K:$K, MINIFS('Activity map'!$K:$K, 'Activity map'!$A:$A, $A19, 'Activity map'!$H:$H, "=TRUE")) -> 8940 | N19: =MINIFS('Activity map'!$C:$C, 'Activity map'!$A:$A, $A19, 'Activity map'!$H:$H, "=TRUE", 'Activity map'!$E:$E, $T19) -> 8940 | O19: =IF(MIN(F19,H19,J19,L19) = 0, "Done!", MIN(F19,H19,J19,L19) / 24) -> 0.00069444444 | P19: =IF($M19=0, "-", VLOOKUP($M19, 'List of log slots'!$A:$C, 2, FALSE)) -> Rum | Q19: =IFERROR(__xludf.DUMMYFUNCTION("IF(ISERROR(FILTER('Activity map'!$C:$C, ('Activity map'!$A:$A=$A19)*('Activity map'!$F:$F=FALSE))), 0, COUNTA(UNIQUE(FILTER('Activity map'!$C:$C, ('Activity map'!$A:$A=$A19)*('Activity map'!$F:$F=FALSE)))))"),30.0) -> 30 | R19: =IFERROR(__xludf.DUMMYFUNCTION("IF(ISERROR(FILTER('Activity map'!$C:$C, 'Activity map'!$A:$A=$A19)), 0, COUNTA(UNIQUE(FILTER('Activity map'!$C:$C, 'Activity map'!$A:$A=$A19))))"),30.0) -> 30 | S19: =1 - Q19/R19 -> 0 | T19: =IFERROR(__xludf.DUMMYFUNCTION("IF(ISERROR(FILTER('Activity map'!$E:$E, ('Activity map'!$A:$A=$A19)*('Activity map'!$F:$F=FALSE))), ""-"", MIN(UNIQUE(FILTER('Activity map'!$E:$E, ('Activity map'!$A:$A=$A19)*('Activity map'!$F:$F=FALSE)))))"),2.0) -> 2 | U19: =IF($N19=0, "-", VLOOKUP($N19, 'List of log slots'!$A:$C, 2, FALSE)) -> Rum
A20: 4 | B20: =VLOOKUP($A20, 'Completion rates'!$A:$E, 2, FALSE) -> Killing araxxor (on task) | C20: =IF(Notes!$E$27, VLOOKUP($A20, 'Completion rates'!$A:$E, 4, FALSE), VLOOKUP($A20, 'Completion rates'!$A:$E, 3, FALSE)) -> 45 | D20: =VLOOKUP($A20, 'Completion rates'!$A:$E, 5, FALSE) -> 0 | E20: =IF(SUMIFS('Activity map'!$O:$O, 'Activity map'!$A:$A, A20, 'Activity map'!$H:$H, "=TRUE") = 0, "n/a", 1/SUMIFS('Activity map'!$O:$O, 'Activity map'!$A:$A, A20, 'Activity map'!$H:$H, "=TRUE")) -> 0.82771073 | F20: =IF(OR(ISBLANK(C20), E20 = "n/a"), "", E20/C20 + D20) -> 0.018393572 | G20: =IF(MINIFS('Activity map'!$N:$N, 'Activity map'!$A:$A, A20, 'Activity map'!$H:$H, "=TRUE") = 0, "n/a", MINIFS('Activity map'!$N:$N, 'Activity map'!$A:$A, A20, 'Activity map'!$H:$H, "=TRUE")) -> 1500 | H20: =IF(OR(ISBLANK(C20), G20 = "n/a"), "", G20/C20 + D20) -> 33.333333 | I20: =IF(MINIFS('Activity map'!$M:$M, 'Activity map'!$A:$A, A20, 'Activity map'!$H:$H, "=TRUE") = 0, "n/a", MINIFS('Activity map'!$M:$M, 'Activity map'!$A:$A, A20, 'Activity map'!$H:$H, "=TRUE")) -> n/a | J20: =IF(OR(ISBLANK(C20), I20 = "n/a"), "", I20/C20 + D20) | K20: =IF(MINIFS('Activity map'!$L:$L, 'Activity map'!$A:$A, A20, 'Activity map'!$H:$H, "=TRUE") = 0, "n/a", MINIFS('Activity map'!$L:$L, 'Activity map'!$A:$A, A20, 'Activity map'!$H:$H, "=TRUE")) -> n/a | L20: =IF(OR(ISBLANK(C20), K20 = "n/a"), "", K20/C20 + D20) | M20: =MINIFS('Activity map'!$C:$C, 'Activity map'!$A:$A, $A20, 'Activity map'!$H:$H, "=TRUE", 'Activity map'!$K:$K, MINIFS('Activity map'!$K:$K, 'Activity map'!$A:$A, $A20, 'Activity map'!$H:$H, "=TRUE")) -> 29781 | N20: =MINIFS('Activity map'!$C:$C, 'Activity map'!$A:$A, $A20, 'Activity map'!$H:$H, "=TRUE", 'Activity map'!$E:$E, $T20) -> 1249 | O20: =IF(MIN(F20,H20,J20,L20) = 0, "Done!", MIN(F20,H20,J20,L20) / 24) -> 0.00076639883 | P20: =IF($M20=0, "-", VLOOKUP($M20, 'List of log slots'!$A:$C, 2, FALSE)) -> Coagulated venom | Q20: =IFERROR(__xludf.DUMMYFUNCTION("IF(ISERROR(FILTER('Activity map'!$C:$C, ('Activity map'!$A:$A=$A20)*('Activity map'!$F:$F=FALSE))), 0, COUNTA(UNIQUE(FILTER('Activity map'!$C:$C, ('Activity map'!$A:$A=$A20)*('Activity map'!$F:$F=FALSE)))))"),12.0) -> 12 | R20: =IFERROR(__xludf.DUMMYFUNCTION("IF(ISERROR(FILTER('Activity map'!$C:$C, 'Activity map'!$A:$A=$A20)), 0, COUNTA(UNIQUE(FILTER('Activity map'!$C:$C, 'Activity map'!$A:$A=$A20))))"),12.0) -> 12 | S20: =1 - Q20/R20 -> 0 | T20: =IFERROR(__xludf.DUMMYFUNCTION("IF(ISERROR(FILTER('Activity map'!$E:$E, ('Activity map'!$A:$A=$A20)*('Activity map'!$F:$F=FALSE))), ""-"", MIN(UNIQUE(FILTER('Activity map'!$E:$E, ('Activity map'!$A:$A=$A20)*('Activity map'!$F:$F=FALSE)))))"),5.0) -> 5 | U20: =IF($N20=0, "-", VLOOKUP($N20, 'List of log slots'!$A:$C, 2, FALSE)) -> Dragon spear
A21: 100 | B21: =VLOOKUP($A21, 'Completion rates'!$A:$E, 2, FALSE) -> Earning volcanic mine reward points | C21: =IF(Notes!$E$27, VLOOKUP($A21, 'Completion rates'!$A:$E, 4, FALSE), VLOOKUP($A21, 'Completion rates'!$A:$E, 3, FALSE)) -> 10000 | D21: =VLOOKUP($A21, 'Completion rates'!$A:$E, 5, FALSE) -> 0 | E21: =IF(SUMIFS('Activity map'!$O:$O, 'Activity map'!$A:$A, A21, 'Activity map'!$H:$H, "=TRUE") = 0, "n/a", 1/SUMIFS('Activity map'!$O:$O, 'Activity map'!$A:$A, A21, 'Activity map'!$H:$H, "=TRUE")) -> 400000 | F21: =IF(OR(ISBLANK(C21), E21 = "n/a"), "", E21/C21 + D21) -> 40 | G21: =IF(MINIFS('Activity map'!$N:$N, 'Activity map'!$A:$A, A21, 'Activity map'!$H:$H, "=TRUE") = 0, "n/a", MINIFS('Activity map'!$N:$N, 'Activity map'!$A:$A, A21, 'Activity map'!$H:$H, "=TRUE")) -> n/a | H21: =IF(OR(ISBLANK(C21), G21 = "n/a"), "", G21/C21 + D21) | I21: =IF(MINIFS('Activity map'!$M:$M, 'Activity map'!$A:$A, A21, 'Activity map'!$H:$H, "=TRUE") = 0, "n/a", MINIFS('Activity map'!$M:$M, 'Activity map'!$A:$A, A21, 'Activity map'!$H:$H, "=TRUE")) -> n/a | J21: =IF(OR(ISBLANK(C21), I21 = "n/a"), "", I21/C21 + D21) | K21: =IF(MINIFS('Activity map'!$L:$L, 'Activity map'!$A:$A, A21, 'Activity map'!$H:$H, "=TRUE") = 0, "n/a", MINIFS('Activity map'!$L:$L, 'Activity map'!$A:$A, A21, 'Activity map'!$H:$H, "=TRUE")) -> 200 | L21: =IF(OR(ISBLANK(C21), K21 = "n/a"), "", K21/C21 + D21) -> 0.02 | M21: =MINIFS('Activity map'!$C:$C, 'Activity map'!$A:$A, $A21, 'Activity map'!$H:$H, "=TRUE", 'Activity map'!$K:$K, MINIFS('Activity map'!$K:$K, 'Activity map'!$A:$A, $A21, 'Activity map'!$H:$H, "=TRUE")) -> 21541 | N21: =MINIFS('Activity map'!$C:$C, 'Activity map'!$A:$A, $A21, 'Activity map'!$H:$H, "=TRUE", 'Activity map'!$E:$E, $T21) -> 21541 | O21: =IF(MIN(F21,H21,J21,L21) = 0, "Done!", MIN(F21,H21,J21,L21) / 24) -> 0.00083333333 | P21: =IF($M21=0, "-", VLOOKUP($M21, 'List of log slots'!$A:$C, 2, FALSE)) -> Volcanic mine teleport | Q21: =IFERROR(__xludf.DUMMYFUNCTION("IF(ISERROR(FILTER('Activity map'!$C:$C, ('Activity map'!$A:$A=$A21)*('Activity map'!$F:$F=FALSE))), 0, COUNTA(UNIQUE(FILTER('Activity map'!$C:$C, ('Activity map'!$A:$A=$A21)*('Activity map'!$F:$F=FALSE)))))"),4.0) -> 4 | R21: =IFERROR(__xludf.DUMMYFUNCTION("IF(ISERROR(FILTER('Activity map'!$C:$C, 'Activity map'!$A:$A=$A21)), 0, COUNTA(UNIQUE(FILTER('Activity map'!$C:$C, 'Activity map'!$A:$A=$A21))))"),4.0) -> 4 | S21: =1 - Q21/R21 -> 0 | T21: =IFERROR(__xludf.DUMMYFUNCTION("IF(ISERROR(FILTER('Activity map'!$E:$E, ('Activity map'!$A:$A=$A21)*('Activity map'!$F:$F=FALSE))), ""-"", MIN(UNIQUE(FILTER('Activity map'!$E:$E, ('Activity map'!$A:$A=$A21)*('Activity map'!$F:$F=FALSE)))))"),3.0) -> 3 | U21: =IF($N21=0, "-", VLOOKUP($N21, 'List of log slots'!$A:$C, 2, FALSE)) -> Volcanic mine teleport
